<!DOCTYPE html>
<html lang="en">
<head>
    <meta charset="UTF-8">
    <title>Title</title>
</head>
<body>
<script>
  try {
    // 代码...
  } catch (err) {
    // 错误捕获
  }
</script>
<script>
  try {

    console.log('开始执行 try 中的内容');

    // ...这里没有 error

    console.log('try 中的内容执行完毕');

  } catch (err) {

    console.log('catch 被忽略，因为没有 error');

  }
</script>
<script>
  try {

    console.log('开始执行 try 中的内容');

    lalala; // error，变量未定义！

    console.log('try 的末尾（未执行到此处）');

  } catch (err) {

    console.log(`${err}出现了 error！`);

  }
</script>
<script>
  try {
    setTimeout(function() {
      noSuchVariable; // 脚本将在这里停止运行
    }, 1000);
  } catch (err) {
    console.log('不工作');
  }
</script>
<script>
  setTimeout(
      function() {
        try {
          noSuchVariable; // try...catch 处理 error 了！
        } catch (err) {
          console.log('error 被在这里捕获了！');
        }
      }, 1000,
  );
</script>
<script>
  try {
    lalala; // error, variable is not defined!
  } catch (err) {
    console.log(err.name); // ReferenceError
    console.log(err.message); // lalala is not defined
    console.log(err.stack); // ReferenceError: lalala is not defined at (...call stack)

    // 也可以将一个 error 作为整体显示出来
    // error 信息被转换为像 "name: message" 这样的字符串
    console.log(err); // ReferenceError: lalala is not defined
  }
</script>
<script>
  let json = '{"name":"John", "age": 30}'; // 来自服务器的数据

  let user = JSON.parse(json); // 将文本表示转换成 JavaScript 对象

  // 现在 user 是一个解析自 json 字符串的有自己属性的对象
  console.log(user.name); // John
  console.log(user.age);  // 30

  let json2 = '{ bad json }';

  try {
    let user2 = JSON.parse(json2); // <-- 当出现 error 时...
    console.log(user2.name); // 不工作

  } catch (err) {
    // ...执行会跳转到这里并继续执行
    console.log('很抱歉，数据有错误，我们会尝试再请求一次。');
    console.log(err.name);
    console.log(err.message);
  }
</script>
<script>
  let json3 = '{ "age": 30 }'; // 不完整的数据
  try {
    let user3 = JSON.parse(json3); // <-- 没有 error
    console.log(user3.name); // 没有 name！
  } catch (err) {
    console.log('doesn\'t execute');
  }
</script>
<script>
  let error = new Error('Things happen o_O');

  console.log(error.name); // Error
  console.log(error.message); // Things happen o_O
</script>
<script>
  try {
    JSON.parse('{ bad json o_O }');
  } catch (err) {
    console.log(err.name); // SyntaxError
    console.log(err.message); // Unexpected token b in JSON at position 2
  }
</script>
<script>
  let json4 = '{ "age": 30 }'; // 不完整的数据

  try {
    let user4 = JSON.parse(json4); // <-- 没有 error

    if (!user4.name) {
      throw new SyntaxError('数据不全：没有 name'); // (*)
    }

    console.log(user4.name);
  } catch (err) {
    console.log('JSON Error: ' + err.message); // JSON Error: 数据不全：没有 name
  }
</script>
<script>
  'use strict';
  let json5 = '{ "age": 30 }'; // 不完整的数据

  try {
    user5 = JSON.parse(json5);

    if (!user5.name) {
      throw new SyntaxError('数据不全：没有 name');
    }

    blabla(); // 预料之外的 error

  } catch (err) {
    if (err instanceof SyntaxError) {
      console.log('JSON Error: ' + err.message);
    } else if (err instanceof ReferenceError) {
      console.log(err.name, err.message);
    } else {
      throw err;
    }
  }
</script>
<script>
  'use strict';
  let json6 = '{"name":"John", "age": 30}';

  try {
    let user6 = JSON.parse(json6);

    if (!user6.name) {
      throw new SyntaxError('数据不全：没有 name');
    }

    blabla(); // 预料之外的 error

  } catch (err) {
    if (err instanceof SyntaxError) {
      console.log('JSON Error: ' + err.message);
    } else if (err instanceof ReferenceError) {
      console.log(err.name, err.message);
    } else {
      throw err;
    }
  }
</script>
<script>
  'use strict;';

  function readData() {
    let json7 = '{ "age": 30 }';

    try {
      blabla(); // error!
    } catch (err) {
      if (!(err instanceof SyntaxError)) {
        throw err; // 再次抛出（不知道如何处理它）
      }
    }
  }

  try {
    readData();
  } catch (err) {
    console.log('External catch got: ' + err); // 捕获了它！
  }
</script>
<script>
  try {
    console.log('try');
    if (confirm('Make an error?')) {
      BAD_CODE();
    }
  } catch (err) {
    console.log('catch');
  } finally {
    console.log('finally');
  }
</script>
<script>
  let num = +prompt('输入一个正整数？', 35);

  let diff, result;

  function fib(n) {
    if (n < 0 || Math.trunc(n) != n) {
      throw new Error('不能是负数，并且必须是整数。');
    }
    return n <= 1 ? n : fib(n - 1) + fib(n - 2);
  }

  let start = Date.now();
  try {
    result = fib(num);
  } catch (err) {
    result = 0;
  } finally {
    diff = Date.now() - start;
  }

  console.log(result || 'error出现了 ');
  console.log(`执行花费了 ${diff}ms`);
</script>
<script>
  function func() {
    try {
      return 1;
    } catch (err) {

    } finally {
      console.log('return or finally');
    }
  }

  console.log(func()); // 先执行 finally 中的 alert，然后执行这个 alert
</script>
<script>
  function func1() {
    try {

    } finally {

    }
  }
</script>
<script>
  window.onerror = function(message, url, line, col, error) {
    console.log(`${message}\n At ${line}:${col} of ${url}`);
  };

  function readData2() {
    badFunc(); // 啊，出问题了！
  }

  readData2();
</script>
<script>
  function f10() {
    try {
      console.log('start');
      throw new Error('一个 error');
    } catch (err) {
      // ...
      if ('无法处理此 error') {
        throw err;
      }

    } finally {
      console.log('cleanup!');
    }
  }

  f10(); // cleanup!
</script>
</body>
</html>
