<!DOCTYPE html>
<html lang="en">
<head>
    <meta charset="UTF-8">
    <title>Title</title>
</head>
<body>
<script>
  fetch('https://no-such-server.blabla').then(
      response => response.json(),
  ).catch(
      err => console.log(err),
  );
</script>
<script>
  fetch('/article/promise-chaining/user.json').then(
      response => response.json(),
  ).then(
      user => fetch(`https://api.github.com/users/${user.name}`),
  ).then(
      response => response.json(),
  ).then(
      githubUser => new Promise(
          (resolve, reject) => {
            let img = document.createElement('img');
            img.src = githubUser.avatar_url;
            img.className = 'promise-avatar-example';
            document.body.append(img);

            setTimeout(
                () => {
                  img.remove();
                  resolve(githubUser);
                },
                3000,
            );
          },
      ),
  ).catch(
      error => console.log(error.message),
  );
</script>
<script>
  new Promise(
      (resolve, reject) => {
        throw  new Error('Whoops!');
      },
  ).catch(
      console.log,
  );
</script>
<script>
  new Promise(
      (resolve, reject) => {
        reject(new Error('Whoops!'));
      },
  ).catch(
      console.log,
  );
</script>
<script>
  new Promise(
      (resolve, reject) => {
        resolve('ok');
      },
  ).then(
      (result) => {
        throw new Error('Whoops!');
      },
  ).catch(
      console.log,
  );
  new Promise(
      (resolve, reject) => {
        resolve('ok');
      },
  ).then(
      (result) => {
        blabla();
      },
  ).catch(
      console.log,
  );
</script>
<script>
  new Promise(
      (resolve, reject) => {
        throw new Error('Whoops!');
      },
  ).catch(
      function(error) {
        console.log('The error is handled, continue normally');
      },
  ).then(
      () => console.log('Next successful handler runs'),
  );
</script>
<script>
  new Promise(
      (resolve, reject) => {
        throw  new Error('Whoops!');
      },
  ).catch(
      function(error) {
        if (error instanceof URIError) {

        } else {
          console.log('Can\'t handle such error');
          throw  error;
        }
      },
  ).then(
      function() {

      },
  ).catch(
      error => {
        console.log(`The unknown error has occurred: ${error}`);
      },
  );
</script>
<script>
  new Promise(
      function() {
        noSuchFunction();
      },
  ).then(
      () => {},
  );
</script>
<script>
  window.addEventListener(
      'unhandledrejection',
      function(event) {
        // 这个事件对象有两个特殊的属性：
        console.log(event.promise); // [object Promise] —— 生成该全局 error 的 promise
        console.log(event.reason); // Error: Whoops! —— 未处理的 error 对象
      },
  );

  new Promise(
      function() {
        throw  new Error('Whoops! addEventListener');
      },
  );
</script>
<script>
  new Promise(
      function(resolve, reject) {
        setTimeout(
            () => {
              throw new Error('Whoops! in setTimeout');
            },
            1000,
        );
      },
  ).catch(
      console.log,
  );
</script>
</body>
</html>
